[0m15:09:13.305580 [debug] [MainThread]: Sending event: {'category': 'dbt', 'action': 'invocation', 'label': 'start', 'context': [<snowplow_tracker.self_describing_json.SelfDescribingJson object at 0x0000019A77A263C0>, <snowplow_tracker.self_describing_json.SelfDescribingJson object at 0x0000019A7A45DBD0>, <snowplow_tracker.self_describing_json.SelfDescribingJson object at 0x0000019A7A45DA90>]}


============================== 15:09:13.311199 | e3f112d6-207c-4d8a-8643-8359ef09e67a ==============================
[0m15:09:13.311199 [info ] [MainThread]: Running with dbt=1.8.9
[0m15:09:13.311993 [debug] [MainThread]: running dbt with arguments {'printer_width': '80', 'indirect_selection': 'eager', 'write_json': 'True', 'log_cache_events': 'False', 'partial_parse': 'True', 'cache_selected_only': 'False', 'warn_error': 'None', 'version_check': 'True', 'fail_fast': 'False', 'log_path': 'logs', 'profiles_dir': 'C:\\Users\\Jose Ramirez\\.dbt', 'debug': 'False', 'use_colors': 'True', 'use_experimental_parser': 'False', 'no_print': 'None', 'quiet': 'False', 'empty': 'None', 'log_format': 'default', 'invocation_command': 'dbt init finance-data-pipeline', 'static_parser': 'True', 'introspect': 'True', 'target_path': 'None', 'warn_error_options': 'WarnErrorOptions(include=[], exclude=[])', 'send_anonymous_usage_stats': 'True'}
[0m15:09:22.937123 [debug] [MainThread]: Starter project path: C:\Users\Jose Ramirez\OneDrive\Documentos\AA. Self Learning\Entrevista Superintendencia\finance_data_pipeline\dbt-env\Lib\site-packages\dbt\include\starter_project
[0m15:09:22.956713 [info ] [MainThread]: 
Your new dbt project "finance_data_pipeline" was created!

For more information on how to configure the profiles.yml file,
please consult the dbt documentation here:

  https://docs.getdbt.com/docs/configure-your-profile

One more thing:

Need help? Don't hesitate to reach out to us via GitHub issues or on Slack:

  https://community.getdbt.com/

Happy modeling!

[0m15:09:22.957673 [info ] [MainThread]: Setting up your profile.
[0m15:09:29.443939 [info ] [MainThread]: No sample profile found for clickhouse.
[0m15:09:29.445205 [debug] [MainThread]: Command `dbt init` succeeded at 15:09:29.445055 after 16.30 seconds
[0m15:09:29.445602 [debug] [MainThread]: Sending event: {'category': 'dbt', 'action': 'invocation', 'label': 'end', 'context': [<snowplow_tracker.self_describing_json.SelfDescribingJson object at 0x0000019A7A675A70>, <snowplow_tracker.self_describing_json.SelfDescribingJson object at 0x0000019A7A68B890>, <snowplow_tracker.self_describing_json.SelfDescribingJson object at 0x0000019A7A68D8C0>]}
[0m15:09:29.445997 [debug] [MainThread]: Flushing usage events
[0m23:13:59.158212 [debug] [MainThread]: Sending event: {'category': 'dbt', 'action': 'invocation', 'label': 'start', 'context': [<snowplow_tracker.self_describing_json.SelfDescribingJson object at 0x0000027C7330A270>, <snowplow_tracker.self_describing_json.SelfDescribingJson object at 0x0000027C75D39950>, <snowplow_tracker.self_describing_json.SelfDescribingJson object at 0x0000027C75D38B90>]}


============================== 23:13:59.167955 | 58f3a750-498a-4e4b-8e55-d2a7286243be ==============================
[0m23:13:59.167955 [info ] [MainThread]: Running with dbt=1.8.9
[0m23:13:59.169096 [debug] [MainThread]: running dbt with arguments {'printer_width': '80', 'indirect_selection': 'eager', 'write_json': 'True', 'log_cache_events': 'False', 'partial_parse': 'True', 'cache_selected_only': 'False', 'warn_error': 'None', 'fail_fast': 'False', 'debug': 'False', 'log_path': 'logs', 'profiles_dir': 'C:\\Users\\Jose Ramirez\\.dbt', 'version_check': 'True', 'use_colors': 'True', 'use_experimental_parser': 'False', 'no_print': 'None', 'quiet': 'False', 'empty': 'None', 'log_format': 'default', 'invocation_command': 'dbt debug', 'warn_error_options': 'WarnErrorOptions(include=[], exclude=[])', 'introspect': 'True', 'target_path': 'None', 'static_parser': 'True', 'send_anonymous_usage_stats': 'True'}
[0m23:13:59.232940 [info ] [MainThread]: dbt version: 1.8.9
[0m23:13:59.233714 [info ] [MainThread]: python version: 3.13.2
[0m23:13:59.234362 [info ] [MainThread]: python path: C:\Users\Jose Ramirez\OneDrive\Documentos\AA. Self Learning\Entrevista Superintendencia\finance_data_pipeline\dbt-env\Scripts\python.exe
[0m23:13:59.234956 [info ] [MainThread]: os info: Windows-11-10.0.26100-SP0
[0m23:13:59.351990 [info ] [MainThread]: Using profiles dir at C:\Users\Jose Ramirez\.dbt
[0m23:13:59.353011 [info ] [MainThread]: Using profiles.yml file at C:\Users\Jose Ramirez\.dbt\profiles.yml
[0m23:13:59.353644 [info ] [MainThread]: Using dbt_project.yml file at C:\Users\Jose Ramirez\OneDrive\Documentos\AA. Self Learning\Entrevista Superintendencia\finance_data_pipeline\dbt_project.yml
[0m23:13:59.355467 [info ] [MainThread]: adapter type: clickhouse
[0m23:13:59.356064 [info ] [MainThread]: adapter version: 1.8.9
[0m23:13:59.356642 [info ] [MainThread]: Configuration:
[0m23:13:59.357135 [info ] [MainThread]:   profiles.yml file [[32mOK found and valid[0m]
[0m23:13:59.357679 [info ] [MainThread]:   dbt_project.yml file [[31mERROR not found[0m]
[0m23:13:59.358164 [info ] [MainThread]: Required dependencies:
[0m23:13:59.358785 [debug] [MainThread]: Executing "git --help"
[0m23:13:59.422332 [debug] [MainThread]: STDOUT: "b"usage: git [-v | --version] [-h | --help] [-C <path>] [-c <name>=<value>]\n           [--exec-path[=<path>]] [--html-path] [--man-path] [--info-path]\n           [-p | --paginate | -P | --no-pager] [--no-replace-objects] [--bare]\n           [--git-dir=<path>] [--work-tree=<path>] [--namespace=<name>]\n           [--config-env=<name>=<envvar>] <command> [<args>]\n\nThese are common Git commands used in various situations:\n\nstart a working area (see also: git help tutorial)\n   clone     Clone a repository into a new directory\n   init      Create an empty Git repository or reinitialize an existing one\n\nwork on the current change (see also: git help everyday)\n   add       Add file contents to the index\n   mv        Move or rename a file, a directory, or a symlink\n   restore   Restore working tree files\n   rm        Remove files from the working tree and from the index\n\nexamine the history and state (see also: git help revisions)\n   bisect    Use binary search to find the commit that introduced a bug\n   diff      Show changes between commits, commit and working tree, etc\n   grep      Print lines matching a pattern\n   log       Show commit logs\n   show      Show various types of objects\n   status    Show the working tree status\n\ngrow, mark and tweak your common history\n   branch    List, create, or delete branches\n   commit    Record changes to the repository\n   merge     Join two or more development histories together\n   rebase    Reapply commits on top of another base tip\n   reset     Reset current HEAD to the specified state\n   switch    Switch branches\n   tag       Create, list, delete or verify a tag object signed with GPG\n\ncollaborate (see also: git help workflows)\n   fetch     Download objects and refs from another repository\n   pull      Fetch from and integrate with another repository or a local branch\n   push      Update remote refs along with associated objects\n\n'git help -a' and 'git help -g' list available subcommands and some\nconcept guides. See 'git help <command>' or 'git help <concept>'\nto read about a specific subcommand or concept.\nSee 'git help git' for an overview of the system.\n""
[0m23:13:59.423179 [debug] [MainThread]: STDERR: "b''"
[0m23:13:59.423821 [info ] [MainThread]:  - git [[32mOK found[0m]

[0m23:13:59.424677 [info ] [MainThread]: Connection:
[0m23:13:59.425462 [info ] [MainThread]:   driver: None
[0m23:13:59.426169 [info ] [MainThread]:   host: host.docker.internal
[0m23:13:59.426895 [info ] [MainThread]:   port: 8123
[0m23:13:59.427891 [info ] [MainThread]:   user: admin
[0m23:13:59.428501 [info ] [MainThread]:   schema: default
[0m23:13:59.429053 [info ] [MainThread]:   retries: 1
[0m23:13:59.429666 [info ] [MainThread]:   database_engine: None
[0m23:13:59.430427 [info ] [MainThread]:   cluster_mode: False
[0m23:13:59.431036 [info ] [MainThread]:   secure: False
[0m23:13:59.431621 [info ] [MainThread]:   verify: True
[0m23:13:59.432125 [info ] [MainThread]:   client_cert: None
[0m23:13:59.432654 [info ] [MainThread]:   client_cert_key: None
[0m23:13:59.433106 [info ] [MainThread]:   connect_timeout: 10
[0m23:13:59.433594 [info ] [MainThread]:   send_receive_timeout: 300
[0m23:13:59.434112 [info ] [MainThread]:   sync_request_timeout: 5
[0m23:13:59.434566 [info ] [MainThread]:   compress_block_size: 1048576
[0m23:13:59.435102 [info ] [MainThread]:   compression: 
[0m23:13:59.435689 [info ] [MainThread]:   check_exchange: True
[0m23:13:59.436247 [info ] [MainThread]:   custom_settings: None
[0m23:13:59.436946 [info ] [MainThread]:   use_lw_deletes: False
[0m23:13:59.437675 [info ] [MainThread]:   allow_automatic_deduplication: False
[0m23:13:59.438377 [info ] [MainThread]:   tcp_keepalive: False
[0m23:13:59.439660 [info ] [MainThread]: Registered adapter: clickhouse=1.8.9
[0m23:14:00.109872 [debug] [MainThread]: Acquiring new clickhouse connection 'debug'
[0m23:14:00.110425 [debug] [MainThread]: Opening a new connection, currently in state init
[0m23:14:27.822460 [debug] [MainThread]: dbt_clickhouse adapter: Got a retryable error when attempting to open a clickhouse connection.
1 attempts remaining. Retrying in 1 seconds.
Error:
Error HTTPConnectionPool(host='host.docker.internal', port=8123): Max retries exceeded with url: /? (Caused by ConnectTimeoutError(<urllib3.connection.HTTPConnection object at 0x0000027C162D7C50>, 'Connection to host.docker.internal timed out. (connect timeout=10)')) executing HTTP request attempt 1 (http://host.docker.internal:8123)
[0m23:14:48.848334 [error] [MainThread]: Encountered an error:

[0m23:14:49.249333 [error] [MainThread]: Traceback (most recent call last):
  File "C:\Users\Jose Ramirez\OneDrive\Documentos\AA. Self Learning\Entrevista Superintendencia\finance_data_pipeline\dbt-env\Lib\site-packages\urllib3\connection.py", line 198, in _new_conn
    sock = connection.create_connection(
        (self._dns_host, self.port),
    ...<2 lines>...
        socket_options=self.socket_options,
    )
  File "C:\Users\Jose Ramirez\OneDrive\Documentos\AA. Self Learning\Entrevista Superintendencia\finance_data_pipeline\dbt-env\Lib\site-packages\urllib3\util\connection.py", line 85, in create_connection
    raise err
  File "C:\Users\Jose Ramirez\OneDrive\Documentos\AA. Self Learning\Entrevista Superintendencia\finance_data_pipeline\dbt-env\Lib\site-packages\urllib3\util\connection.py", line 73, in create_connection
    sock.connect(sa)
    ~~~~~~~~~~~~^^^^
TimeoutError: timed out

The above exception was the direct cause of the following exception:

Traceback (most recent call last):
  File "C:\Users\Jose Ramirez\OneDrive\Documentos\AA. Self Learning\Entrevista Superintendencia\finance_data_pipeline\dbt-env\Lib\site-packages\urllib3\connectionpool.py", line 787, in urlopen
    response = self._make_request(
        conn,
    ...<10 lines>...
        **response_kw,
    )
  File "C:\Users\Jose Ramirez\OneDrive\Documentos\AA. Self Learning\Entrevista Superintendencia\finance_data_pipeline\dbt-env\Lib\site-packages\urllib3\connectionpool.py", line 493, in _make_request
    conn.request(
    ~~~~~~~~~~~~^
        method,
        ^^^^^^^
    ...<6 lines>...
        enforce_content_length=enforce_content_length,
        ^^^^^^^^^^^^^^^^^^^^^^^^^^^^^^^^^^^^^^^^^^^^^^
    )
    ^
  File "C:\Users\Jose Ramirez\OneDrive\Documentos\AA. Self Learning\Entrevista Superintendencia\finance_data_pipeline\dbt-env\Lib\site-packages\urllib3\connection.py", line 445, in request
    self.endheaders()
    ~~~~~~~~~~~~~~~^^
  File "C:\Users\Jose Ramirez\AppData\Local\Programs\Python\Python313\Lib\http\client.py", line 1333, in endheaders
    self._send_output(message_body, encode_chunked=encode_chunked)
    ~~~~~~~~~~~~~~~~~^^^^^^^^^^^^^^^^^^^^^^^^^^^^^^^^^^^^^^^^^^^^^
  File "C:\Users\Jose Ramirez\AppData\Local\Programs\Python\Python313\Lib\http\client.py", line 1093, in _send_output
    self.send(msg)
    ~~~~~~~~~^^^^^
  File "C:\Users\Jose Ramirez\AppData\Local\Programs\Python\Python313\Lib\http\client.py", line 1037, in send
    self.connect()
    ~~~~~~~~~~~~^^
  File "C:\Users\Jose Ramirez\OneDrive\Documentos\AA. Self Learning\Entrevista Superintendencia\finance_data_pipeline\dbt-env\Lib\site-packages\urllib3\connection.py", line 276, in connect
    self.sock = self._new_conn()
                ~~~~~~~~~~~~~~^^
  File "C:\Users\Jose Ramirez\OneDrive\Documentos\AA. Self Learning\Entrevista Superintendencia\finance_data_pipeline\dbt-env\Lib\site-packages\urllib3\connection.py", line 207, in _new_conn
    raise ConnectTimeoutError(
    ...<2 lines>...
    ) from e
urllib3.exceptions.ConnectTimeoutError: (<urllib3.connection.HTTPConnection object at 0x0000027C162D7C50>, 'Connection to host.docker.internal timed out. (connect timeout=10)')

The above exception was the direct cause of the following exception:

Traceback (most recent call last):
  File "C:\Users\Jose Ramirez\OneDrive\Documentos\AA. Self Learning\Entrevista Superintendencia\finance_data_pipeline\dbt-env\Lib\site-packages\clickhouse_connect\driver\httpclient.py", line 449, in _raw_request
    response = self.http.request(method, url, **kwargs)
  File "C:\Users\Jose Ramirez\OneDrive\Documentos\AA. Self Learning\Entrevista Superintendencia\finance_data_pipeline\dbt-env\Lib\site-packages\urllib3\_request_methods.py", line 143, in request
    return self.request_encode_body(
           ~~~~~~~~~~~~~~~~~~~~~~~~^
        method, url, fields=fields, headers=headers, **urlopen_kw
        ^^^^^^^^^^^^^^^^^^^^^^^^^^^^^^^^^^^^^^^^^^^^^^^^^^^^^^^^^
    )
    ^
  File "C:\Users\Jose Ramirez\OneDrive\Documentos\AA. Self Learning\Entrevista Superintendencia\finance_data_pipeline\dbt-env\Lib\site-packages\urllib3\_request_methods.py", line 278, in request_encode_body
    return self.urlopen(method, url, **extra_kw)
           ~~~~~~~~~~~~^^^^^^^^^^^^^^^^^^^^^^^^^
  File "C:\Users\Jose Ramirez\OneDrive\Documentos\AA. Self Learning\Entrevista Superintendencia\finance_data_pipeline\dbt-env\Lib\site-packages\urllib3\poolmanager.py", line 443, in urlopen
    response = conn.urlopen(method, u.request_uri, **kw)
  File "C:\Users\Jose Ramirez\OneDrive\Documentos\AA. Self Learning\Entrevista Superintendencia\finance_data_pipeline\dbt-env\Lib\site-packages\urllib3\connectionpool.py", line 871, in urlopen
    return self.urlopen(
           ~~~~~~~~~~~~^
        method,
        ^^^^^^^
    ...<13 lines>...
        **response_kw,
        ^^^^^^^^^^^^^^
    )
    ^
  File "C:\Users\Jose Ramirez\OneDrive\Documentos\AA. Self Learning\Entrevista Superintendencia\finance_data_pipeline\dbt-env\Lib\site-packages\urllib3\connectionpool.py", line 841, in urlopen
    retries = retries.increment(
        method, url, error=new_e, _pool=self, _stacktrace=sys.exc_info()[2]
    )
  File "C:\Users\Jose Ramirez\OneDrive\Documentos\AA. Self Learning\Entrevista Superintendencia\finance_data_pipeline\dbt-env\Lib\site-packages\urllib3\util\retry.py", line 519, in increment
    raise MaxRetryError(_pool, url, reason) from reason  # type: ignore[arg-type]
    ^^^^^^^^^^^^^^^^^^^^^^^^^^^^^^^^^^^^^^^^^^^^^^^^^^^
urllib3.exceptions.MaxRetryError: HTTPConnectionPool(host='host.docker.internal', port=8123): Max retries exceeded with url: /? (Caused by ConnectTimeoutError(<urllib3.connection.HTTPConnection object at 0x0000027C162D7C50>, 'Connection to host.docker.internal timed out. (connect timeout=10)'))

The above exception was the direct cause of the following exception:

Traceback (most recent call last):
  File "C:\Users\Jose Ramirez\OneDrive\Documentos\AA. Self Learning\Entrevista Superintendencia\finance_data_pipeline\dbt-env\Lib\site-packages\dbt\adapters\clickhouse\httpclient.py", line 58, in _create_client
    return clickhouse_connect.get_client(
           ~~~~~~~~~~~~~~~~~~~~~~~~~~~~~^
        host=credentials.host,
        ^^^^^^^^^^^^^^^^^^^^^^
    ...<12 lines>...
        settings=self._conn_settings,
        ^^^^^^^^^^^^^^^^^^^^^^^^^^^^^
    )
    ^
  File "C:\Users\Jose Ramirez\OneDrive\Documentos\AA. Self Learning\Entrevista Superintendencia\finance_data_pipeline\dbt-env\Lib\site-packages\clickhouse_connect\driver\__init__.py", line 122, in create_client
    return HttpClient(interface, host, port, username, password, database, access_token,
                      settings=settings, **kwargs)
  File "C:\Users\Jose Ramirez\OneDrive\Documentos\AA. Self Learning\Entrevista Superintendencia\finance_data_pipeline\dbt-env\Lib\site-packages\clickhouse_connect\driver\httpclient.py", line 161, in __init__
    super().__init__(database=database,
    ~~~~~~~~~~~~~~~~^^^^^^^^^^^^^^^^^^^
                     uri=self.url,
                     ^^^^^^^^^^^^^
    ...<3 lines>...
                     apply_server_timezone=apply_server_timezone,
                     ^^^^^^^^^^^^^^^^^^^^^^^^^^^^^^^^^^^^^^^^^^^^
                     show_clickhouse_errors=show_clickhouse_errors)
                     ^^^^^^^^^^^^^^^^^^^^^^^^^^^^^^^^^^^^^^^^^^^^^^
  File "C:\Users\Jose Ramirez\OneDrive\Documentos\AA. Self Learning\Entrevista Superintendencia\finance_data_pipeline\dbt-env\Lib\site-packages\clickhouse_connect\driver\client.py", line 69, in __init__
    self._init_common_settings(apply_server_timezone)
    ~~~~~~~~~~~~~~~~~~~~~~~~~~^^^^^^^^^^^^^^^^^^^^^^^
  File "C:\Users\Jose Ramirez\OneDrive\Documentos\AA. Self Learning\Entrevista Superintendencia\finance_data_pipeline\dbt-env\Lib\site-packages\clickhouse_connect\driver\client.py", line 74, in _init_common_settings
    tuple(self.command('SELECT version(), timezone()', use_database=False))
          ~~~~~~~~~~~~^^^^^^^^^^^^^^^^^^^^^^^^^^^^^^^^^^^^^^^^^^^^^^^^^^^^
  File "C:\Users\Jose Ramirez\OneDrive\Documentos\AA. Self Learning\Entrevista Superintendencia\finance_data_pipeline\dbt-env\Lib\site-packages\clickhouse_connect\driver\httpclient.py", line 361, in command
    response = self._raw_request(payload, params, headers, method, fields=fields, server_wait=False)
  File "C:\Users\Jose Ramirez\OneDrive\Documentos\AA. Self Learning\Entrevista Superintendencia\finance_data_pipeline\dbt-env\Lib\site-packages\clickhouse_connect\driver\httpclient.py", line 461, in _raw_request
    raise OperationalError(f'Error {ex} executing HTTP request attempt {attempts}{err_url}') from ex
clickhouse_connect.driver.exceptions.OperationalError: Error HTTPConnectionPool(host='host.docker.internal', port=8123): Max retries exceeded with url: /? (Caused by ConnectTimeoutError(<urllib3.connection.HTTPConnection object at 0x0000027C162D7C50>, 'Connection to host.docker.internal timed out. (connect timeout=10)')) executing HTTP request attempt 1 (http://host.docker.internal:8123)

The above exception was the direct cause of the following exception:

Traceback (most recent call last):
  File "C:\Users\Jose Ramirez\OneDrive\Documentos\AA. Self Learning\Entrevista Superintendencia\finance_data_pipeline\dbt-env\Lib\site-packages\dbt\adapters\base\connections.py", line 237, in retry_connection
    connection.handle = connect()
                        ~~~~~~~^^
  File "C:\Users\Jose Ramirez\OneDrive\Documentos\AA. Self Learning\Entrevista Superintendencia\finance_data_pipeline\dbt-env\Lib\site-packages\dbt\adapters\clickhouse\connections.py", line 45, in connect
    return get_db_client(credentials)
  File "C:\Users\Jose Ramirez\OneDrive\Documentos\AA. Self Learning\Entrevista Superintendencia\finance_data_pipeline\dbt-env\Lib\site-packages\dbt\adapters\clickhouse\dbclient.py", line 66, in get_db_client
    return ChHttpClient(credentials)
  File "C:\Users\Jose Ramirez\OneDrive\Documentos\AA. Self Learning\Entrevista Superintendencia\finance_data_pipeline\dbt-env\Lib\site-packages\dbt\adapters\clickhouse\dbclient.py", line 88, in __init__
    self._client = self._create_client(credentials)
                   ~~~~~~~~~~~~~~~~~~~^^^^^^^^^^^^^
  File "C:\Users\Jose Ramirez\OneDrive\Documentos\AA. Self Learning\Entrevista Superintendencia\finance_data_pipeline\dbt-env\Lib\site-packages\dbt\adapters\clickhouse\httpclient.py", line 75, in _create_client
    raise ChRetryableException(str(ex)) from ex
dbt.adapters.clickhouse.dbclient.ChRetryableException: Error HTTPConnectionPool(host='host.docker.internal', port=8123): Max retries exceeded with url: /? (Caused by ConnectTimeoutError(<urllib3.connection.HTTPConnection object at 0x0000027C162D7C50>, 'Connection to host.docker.internal timed out. (connect timeout=10)')) executing HTTP request attempt 1 (http://host.docker.internal:8123)

During handling of the above exception, another exception occurred:

Traceback (most recent call last):
  File "C:\Users\Jose Ramirez\OneDrive\Documentos\AA. Self Learning\Entrevista Superintendencia\finance_data_pipeline\dbt-env\Lib\site-packages\urllib3\util\connection.py", line 73, in create_connection
    sock.connect(sa)
    ~~~~~~~~~~~~^^^^
TimeoutError: timed out

During handling of the above exception, another exception occurred:

Traceback (most recent call last):
  File "C:\Users\Jose Ramirez\OneDrive\Documentos\AA. Self Learning\Entrevista Superintendencia\finance_data_pipeline\dbt-env\Lib\site-packages\dbt\cli\requires.py", line 138, in wrapper
    result, success = func(*args, **kwargs)
                      ~~~~^^^^^^^^^^^^^^^^^
  File "C:\Users\Jose Ramirez\OneDrive\Documentos\AA. Self Learning\Entrevista Superintendencia\finance_data_pipeline\dbt-env\Lib\site-packages\dbt\cli\requires.py", line 101, in wrapper
    return func(*args, **kwargs)
  File "C:\Users\Jose Ramirez\OneDrive\Documentos\AA. Self Learning\Entrevista Superintendencia\finance_data_pipeline\dbt-env\Lib\site-packages\dbt\cli\main.py", line 406, in debug
    results = task.run()
  File "C:\Users\Jose Ramirez\OneDrive\Documentos\AA. Self Learning\Entrevista Superintendencia\finance_data_pipeline\dbt-env\Lib\site-packages\dbt\task\debug.py", line 150, in run
    connection_status = self.test_connection()
  File "C:\Users\Jose Ramirez\OneDrive\Documentos\AA. Self Learning\Entrevista Superintendencia\finance_data_pipeline\dbt-env\Lib\site-packages\dbt\task\debug.py", line 471, in test_connection
    connection_result = self.attempt_connection(self.profile)
  File "C:\Users\Jose Ramirez\OneDrive\Documentos\AA. Self Learning\Entrevista Superintendencia\finance_data_pipeline\dbt-env\Lib\site-packages\dbt\task\debug.py", line 449, in attempt_connection
    adapter.debug_query()
    ~~~~~~~~~~~~~~~~~~~^^
  File "C:\Users\Jose Ramirez\OneDrive\Documentos\AA. Self Learning\Entrevista Superintendencia\finance_data_pipeline\dbt-env\Lib\site-packages\dbt\adapters\base\impl.py", line 361, in debug_query
    self.execute("select 1 as id")
    ~~~~~~~~~~~~^^^^^^^^^^^^^^^^^^
  File "C:\Users\Jose Ramirez\OneDrive\Documentos\AA. Self Learning\Entrevista Superintendencia\finance_data_pipeline\dbt-env\Lib\site-packages\dbt\adapters\base\impl.py", line 404, in execute
    return self.connections.execute(sql=sql, auto_begin=auto_begin, fetch=fetch, limit=limit)
           ~~~~~~~~~~~~~~~~~~~~~~~~^^^^^^^^^^^^^^^^^^^^^^^^^^^^^^^^^^^^^^^^^^^^^^^^^^^^^^^^^^
  File "C:\Users\Jose Ramirez\OneDrive\Documentos\AA. Self Learning\Entrevista Superintendencia\finance_data_pipeline\dbt-env\Lib\site-packages\dbt\adapters\clickhouse\connections.py", line 88, in execute
    client = conn.handle
             ^^^^^^^^^^^
  File "C:\Users\Jose Ramirez\OneDrive\Documentos\AA. Self Learning\Entrevista Superintendencia\finance_data_pipeline\dbt-env\Lib\site-packages\dbt\adapters\contracts\connection.py", line 96, in handle
    self._handle.resolve(self)
    ~~~~~~~~~~~~~~~~~~~~^^^^^^
  File "C:\Users\Jose Ramirez\OneDrive\Documentos\AA. Self Learning\Entrevista Superintendencia\finance_data_pipeline\dbt-env\Lib\site-packages\dbt\adapters\contracts\connection.py", line 120, in resolve
    return self.opener(connection)
           ~~~~~~~~~~~^^^^^^^^^^^^
  File "C:\Users\Jose Ramirez\OneDrive\Documentos\AA. Self Learning\Entrevista Superintendencia\finance_data_pipeline\dbt-env\Lib\site-packages\dbt\adapters\clickhouse\connections.py", line 47, in open
    return cls.retry_connection(
           ~~~~~~~~~~~~~~~~~~~~^
        connection,
        ^^^^^^^^^^^
    ...<3 lines>...
        retryable_exceptions=retryable_exceptions,
        ^^^^^^^^^^^^^^^^^^^^^^^^^^^^^^^^^^^^^^^^^^
    )
    ^
  File "C:\Users\Jose Ramirez\OneDrive\Documentos\AA. Self Learning\Entrevista Superintendencia\finance_data_pipeline\dbt-env\Lib\site-packages\dbt\adapters\base\connections.py", line 254, in retry_connection
    return cls.retry_connection(
           ~~~~~~~~~~~~~~~~~~~~^
        connection=connection,
        ^^^^^^^^^^^^^^^^^^^^^^
    ...<5 lines>...
        _attempts=_attempts + 1,
        ^^^^^^^^^^^^^^^^^^^^^^^^
    )
    ^
  File "C:\Users\Jose Ramirez\OneDrive\Documentos\AA. Self Learning\Entrevista Superintendencia\finance_data_pipeline\dbt-env\Lib\site-packages\dbt\adapters\base\connections.py", line 237, in retry_connection
    connection.handle = connect()
                        ~~~~~~~^^
  File "C:\Users\Jose Ramirez\OneDrive\Documentos\AA. Self Learning\Entrevista Superintendencia\finance_data_pipeline\dbt-env\Lib\site-packages\dbt\adapters\clickhouse\connections.py", line 45, in connect
    return get_db_client(credentials)
  File "C:\Users\Jose Ramirez\OneDrive\Documentos\AA. Self Learning\Entrevista Superintendencia\finance_data_pipeline\dbt-env\Lib\site-packages\dbt\adapters\clickhouse\dbclient.py", line 66, in get_db_client
    return ChHttpClient(credentials)
  File "C:\Users\Jose Ramirez\OneDrive\Documentos\AA. Self Learning\Entrevista Superintendencia\finance_data_pipeline\dbt-env\Lib\site-packages\dbt\adapters\clickhouse\dbclient.py", line 88, in __init__
    self._client = self._create_client(credentials)
                   ~~~~~~~~~~~~~~~~~~~^^^^^^^^^^^^^
  File "C:\Users\Jose Ramirez\OneDrive\Documentos\AA. Self Learning\Entrevista Superintendencia\finance_data_pipeline\dbt-env\Lib\site-packages\dbt\adapters\clickhouse\httpclient.py", line 58, in _create_client
    return clickhouse_connect.get_client(
           ~~~~~~~~~~~~~~~~~~~~~~~~~~~~~^
        host=credentials.host,
        ^^^^^^^^^^^^^^^^^^^^^^
    ...<12 lines>...
        settings=self._conn_settings,
        ^^^^^^^^^^^^^^^^^^^^^^^^^^^^^
    )
    ^
  File "C:\Users\Jose Ramirez\OneDrive\Documentos\AA. Self Learning\Entrevista Superintendencia\finance_data_pipeline\dbt-env\Lib\site-packages\clickhouse_connect\driver\__init__.py", line 122, in create_client
    return HttpClient(interface, host, port, username, password, database, access_token,
                      settings=settings, **kwargs)
  File "C:\Users\Jose Ramirez\OneDrive\Documentos\AA. Self Learning\Entrevista Superintendencia\finance_data_pipeline\dbt-env\Lib\site-packages\clickhouse_connect\driver\httpclient.py", line 161, in __init__
    super().__init__(database=database,
    ~~~~~~~~~~~~~~~~^^^^^^^^^^^^^^^^^^^
                     uri=self.url,
                     ^^^^^^^^^^^^^
    ...<3 lines>...
                     apply_server_timezone=apply_server_timezone,
                     ^^^^^^^^^^^^^^^^^^^^^^^^^^^^^^^^^^^^^^^^^^^^
                     show_clickhouse_errors=show_clickhouse_errors)
                     ^^^^^^^^^^^^^^^^^^^^^^^^^^^^^^^^^^^^^^^^^^^^^^
  File "C:\Users\Jose Ramirez\OneDrive\Documentos\AA. Self Learning\Entrevista Superintendencia\finance_data_pipeline\dbt-env\Lib\site-packages\clickhouse_connect\driver\client.py", line 69, in __init__
    self._init_common_settings(apply_server_timezone)
    ~~~~~~~~~~~~~~~~~~~~~~~~~~^^^^^^^^^^^^^^^^^^^^^^^
  File "C:\Users\Jose Ramirez\OneDrive\Documentos\AA. Self Learning\Entrevista Superintendencia\finance_data_pipeline\dbt-env\Lib\site-packages\clickhouse_connect\driver\client.py", line 74, in _init_common_settings
    tuple(self.command('SELECT version(), timezone()', use_database=False))
          ~~~~~~~~~~~~^^^^^^^^^^^^^^^^^^^^^^^^^^^^^^^^^^^^^^^^^^^^^^^^^^^^
  File "C:\Users\Jose Ramirez\OneDrive\Documentos\AA. Self Learning\Entrevista Superintendencia\finance_data_pipeline\dbt-env\Lib\site-packages\clickhouse_connect\driver\httpclient.py", line 361, in command
    response = self._raw_request(payload, params, headers, method, fields=fields, server_wait=False)
  File "C:\Users\Jose Ramirez\OneDrive\Documentos\AA. Self Learning\Entrevista Superintendencia\finance_data_pipeline\dbt-env\Lib\site-packages\clickhouse_connect\driver\httpclient.py", line 449, in _raw_request
    response = self.http.request(method, url, **kwargs)
  File "C:\Users\Jose Ramirez\OneDrive\Documentos\AA. Self Learning\Entrevista Superintendencia\finance_data_pipeline\dbt-env\Lib\site-packages\urllib3\_request_methods.py", line 143, in request
    return self.request_encode_body(
           ~~~~~~~~~~~~~~~~~~~~~~~~^
        method, url, fields=fields, headers=headers, **urlopen_kw
        ^^^^^^^^^^^^^^^^^^^^^^^^^^^^^^^^^^^^^^^^^^^^^^^^^^^^^^^^^
    )
    ^
  File "C:\Users\Jose Ramirez\OneDrive\Documentos\AA. Self Learning\Entrevista Superintendencia\finance_data_pipeline\dbt-env\Lib\site-packages\urllib3\_request_methods.py", line 278, in request_encode_body
    return self.urlopen(method, url, **extra_kw)
           ~~~~~~~~~~~~^^^^^^^^^^^^^^^^^^^^^^^^^
  File "C:\Users\Jose Ramirez\OneDrive\Documentos\AA. Self Learning\Entrevista Superintendencia\finance_data_pipeline\dbt-env\Lib\site-packages\urllib3\poolmanager.py", line 443, in urlopen
    response = conn.urlopen(method, u.request_uri, **kw)
  File "C:\Users\Jose Ramirez\OneDrive\Documentos\AA. Self Learning\Entrevista Superintendencia\finance_data_pipeline\dbt-env\Lib\site-packages\urllib3\connectionpool.py", line 871, in urlopen
    return self.urlopen(
           ~~~~~~~~~~~~^
        method,
        ^^^^^^^
    ...<13 lines>...
        **response_kw,
        ^^^^^^^^^^^^^^
    )
    ^
  File "C:\Users\Jose Ramirez\OneDrive\Documentos\AA. Self Learning\Entrevista Superintendencia\finance_data_pipeline\dbt-env\Lib\site-packages\urllib3\connectionpool.py", line 787, in urlopen
    response = self._make_request(
        conn,
    ...<10 lines>...
        **response_kw,
    )
  File "C:\Users\Jose Ramirez\OneDrive\Documentos\AA. Self Learning\Entrevista Superintendencia\finance_data_pipeline\dbt-env\Lib\site-packages\urllib3\connectionpool.py", line 493, in _make_request
    conn.request(
    ~~~~~~~~~~~~^
        method,
        ^^^^^^^
    ...<6 lines>...
        enforce_content_length=enforce_content_length,
        ^^^^^^^^^^^^^^^^^^^^^^^^^^^^^^^^^^^^^^^^^^^^^^
    )
    ^
  File "C:\Users\Jose Ramirez\OneDrive\Documentos\AA. Self Learning\Entrevista Superintendencia\finance_data_pipeline\dbt-env\Lib\site-packages\urllib3\connection.py", line 445, in request
    self.endheaders()
    ~~~~~~~~~~~~~~~^^
  File "C:\Users\Jose Ramirez\AppData\Local\Programs\Python\Python313\Lib\http\client.py", line 1333, in endheaders
    self._send_output(message_body, encode_chunked=encode_chunked)
    ~~~~~~~~~~~~~~~~~^^^^^^^^^^^^^^^^^^^^^^^^^^^^^^^^^^^^^^^^^^^^^
  File "C:\Users\Jose Ramirez\AppData\Local\Programs\Python\Python313\Lib\http\client.py", line 1093, in _send_output
    self.send(msg)
    ~~~~~~~~~^^^^^
  File "C:\Users\Jose Ramirez\AppData\Local\Programs\Python\Python313\Lib\http\client.py", line 1037, in send
    self.connect()
    ~~~~~~~~~~~~^^
  File "C:\Users\Jose Ramirez\OneDrive\Documentos\AA. Self Learning\Entrevista Superintendencia\finance_data_pipeline\dbt-env\Lib\site-packages\urllib3\connection.py", line 276, in connect
    self.sock = self._new_conn()
                ~~~~~~~~~~~~~~^^
  File "C:\Users\Jose Ramirez\OneDrive\Documentos\AA. Self Learning\Entrevista Superintendencia\finance_data_pipeline\dbt-env\Lib\site-packages\urllib3\connection.py", line 198, in _new_conn
    sock = connection.create_connection(
        (self._dns_host, self.port),
    ...<2 lines>...
        socket_options=self.socket_options,
    )
  File "C:\Users\Jose Ramirez\OneDrive\Documentos\AA. Self Learning\Entrevista Superintendencia\finance_data_pipeline\dbt-env\Lib\site-packages\urllib3\util\connection.py", line 81, in create_connection
    sock.close()
    ~~~~~~~~~~^^
  File "C:\Users\Jose Ramirez\AppData\Local\Programs\Python\Python313\Lib\socket.py", line 501, in close
    def close(self):
    
KeyboardInterrupt

[0m23:14:49.255366 [debug] [MainThread]: Command `dbt debug` failed at 23:14:49.255130 after 50.32 seconds
[0m23:14:49.255847 [debug] [MainThread]: Connection 'debug' was properly closed.
[0m23:14:49.256236 [debug] [MainThread]: Sending event: {'category': 'dbt', 'action': 'invocation', 'label': 'end', 'context': [<snowplow_tracker.self_describing_json.SelfDescribingJson object at 0x0000027C163A2190>, <snowplow_tracker.self_describing_json.SelfDescribingJson object at 0x0000027C1638BAD0>, <snowplow_tracker.self_describing_json.SelfDescribingJson object at 0x0000027C163E2250>]}
[0m23:14:49.256680 [debug] [MainThread]: Flushing usage events
